//go:build !gitaly_test_sha256

package objectpool

import (
	"bytes"
	"fmt"
	"path/filepath"
	"testing"

	"github.com/stretchr/testify/require"
	"gitlab.com/gitlab-org/gitaly/v15/internal/git"
	"gitlab.com/gitlab-org/gitaly/v15/internal/git/localrepo"
	"gitlab.com/gitlab-org/gitaly/v15/internal/testhelper"
)

func TestClone_successful(t *testing.T) {
	t.Parallel()

	ctx := testhelper.Context(t)

	cfg, pool, repoProto := setupObjectPool(t, ctx)
	repo := localrepo.NewTestRepo(t, cfg, repoProto)

	require.NoError(t, pool.clone(ctx, repo))

	require.DirExists(t, pool.FullPath())
	require.DirExists(t, filepath.Join(pool.FullPath(), "objects"))
}

func TestClone_existingPool(t *testing.T) {
	t.Parallel()

	ctx := testhelper.Context(t)

	cfg, pool, repoProto := setupObjectPool(t, ctx)
	repo := localrepo.NewTestRepo(t, cfg, repoProto)

	// The first time around cloning should succeed, but ...
	require.NoError(t, pool.clone(ctx, repo))

	// ... when we try to clone the same pool a second time we should get an error because the
	// destination exists already.
	require.EqualError(t, pool.clone(ctx, repo), fmt.Sprintf(
		"cloning to pool: exit status 128, stderr: \"fatal: destination path '%s' already exists and is not an empty directory.\\n\"",
		pool.FullPath(),
	))
}

func TestClone_fsck(t *testing.T) {
	t.Parallel()

	ctx := testhelper.Context(t)

	cfg, pool, repoProto := setupObjectPool(t, ctx)

	repo := localrepo.NewTestRepo(t, cfg, repoProto)
	repoPath, err := repo.Path()
	require.NoError(t, err)

	// Write a tree into the repository that's known-broken.
	treeID := git.WriteTree(t, cfg, repoPath, []git.TreeEntry{
		{Content: "content", Path: "dup", Mode: "100644"},
		{Content: "content", Path: "dup", Mode: "100644"},
	})

	git.WriteTestCommit(t, cfg, repoPath,
		git.WithParents(),
		git.WithBranch("master"),
		git.WithTree(treeID),
	)

	// While git-clone(1) would normally complain about the broken tree we have just cloned, we
	// don't expect the clone to fail. This is because we know that the tree is already in one
	// of our repositories that we have locally, so raising an error now doesn't make a whole
	// lot of sense in the first place.
	//
	// Note: this works because we use `git clone --local`, which only creates a copy of the
	// repository without performing consistency checks.
	require.NoError(t, pool.clone(ctx, repo))

	// Verify that the broken tree is indeed in the pool repository and that it is reported as
	// broken by git-fsck(1).
	var stderr bytes.Buffer
	fsckCmd := git.NewCommand(t, cfg, "-C", pool.FullPath(), "fsck")
	fsckCmd.Stderr = &stderr

	require.EqualError(t, fsckCmd.Run(), "exit status 1")
	require.Equal(t, fmt.Sprintf("error in tree %s: duplicateEntries: contains duplicate file entries\n", treeID), stderr.String())
}
